<?xml version="1.0"?>
<robot xmlns:xacro="http://ros.org/wiki/xacro">
  <!-- macro for arm base mount -->
  <xacro:macro name="base_mount" params="parent name color *origin">
    <joint name="${name}_joint" type="fixed">
      <insert_block name="origin" />
      <parent link="${parent}"/>
      <child link="${name}_link" />
    </joint>

    <link name="${name}_link">
      <inertial>
        <mass value="${mass}" />
        <origin xyz="0 0 ${l0/2}" />
        <inertia ixx="1.0" ixy="0.0" ixz="0.0"
          iyy="1.0" iyz="0.0"
          izz="1.0" />
      </inertial>

      <visual>
      <origin xyz="0 0 ${l0/2}" />
        <geometry>
        <cylinder length="${l0}" radius="${rb}" />
        </geometry>
        <material name="${color}"/>
      </visual>

      <collision>
      <origin xyz="0 0 ${l0/2}" />
        <geometry>
        <cylinder length="${l0}" radius="${rb}" />
        </geometry>
      </collision>
    </link>
  </xacro:macro>

  <!-- macro for one segment, long -->
  <xacro:macro name="segmentL" params="parent name color llimit ulimit vlimit *origin">
    <joint name="${name}_joint" type="revolute">
      <insert_block name="origin" />
      <parent link="${parent}"/>
      <child link="${name}_link" />
      <axis xyz="0 1 0" />
      <limit lower="${llimit}" upper="${ulimit}" velocity="${vlimit}" effort="30" />
      <!--origin rpy="0 0 0" xyz="0.0 0.0 ${l1+jr}" /-->
    </joint>

    <link name="${name}_link">
      <inertial>
        <mass value="${mass}" />
        <origin rpy="0 0 0" xyz="0 0 ${l1/2}" />
        <inertia ixx="1.0" ixy="0.0" ixz="0.0"
          iyy="1.0" iyz="0.0"
          izz="1.0" />
          <origin rpy="0 0 0" xyz="0 0 ${l1/2}" />
      </inertial>
      <!-- Visual for segment joint -->
      <visual name="${name}_joint_v">
         <geometry>
            <cylinder length="${2*r0}" radius="${jr}" />
         </geometry>
         <origin rpy="${PI/2} 0 0" xyz="0 0 0" />
         <material name="${color}"/>
      </visual>
      <collision name="${name}_joint_c">
         <geometry>
            <cylinder length="${2*r0}" radius="${jr}" />
         </geometry>
         <origin rpy="${PI/2} 0 0" xyz="0 0 0" />
      </collision>
      <!-- Visual for main segment -->
      <visual name="${name}_segmentL_v">
         <geometry>
            <cylinder length="${l1}" radius="${r0}" />
         </geometry>
         <origin rpy="0 0 0" xyz="0 0 ${l1/2}" />
         <material name="${color}"/>
      </visual>
      <collision name="${name}_segmentL_c">
         <geometry>
            <cylinder length="${l1}" radius="${r0}" />
         </geometry>
         <origin rpy="0 0 0" xyz="0 0 ${l1/2}" />
      </collision>
    </link>
  </xacro:macro>

  <!-- macro for one segment, short -->
  <xacro:macro name="segmentS" params="parent name color llimit ulimit vlimit">
    <joint name="${name}_joint" type="revolute">
      <parent link="${parent}"/>
      <child link="${name}_link" />
      <axis xyz="0 1 0" />
      <limit lower="${llimit}" upper="${ulimit}" velocity="${vlimit}" effort="30" />
      <origin rpy="0 0 0" xyz="0.0 0.0 ${l1+jr}" />
    </joint>

    <link name="${name}_link">
      <inertial>
        <mass value="${mass}" />
        <inertia ixx="1.0" ixy="0.0" ixz="0.0"
          iyy="1.0" iyz="0.0"
          izz="1.0" />
        <origin rpy="0 0 0" xyz="0 0 ${l2/2}" />
      </inertial>
      <!-- Visual for segment joint -->
      <visual name="${name}_joint_v">
         <geometry>
            <cylinder length="${2*r0}" radius="${jr}" />
         </geometry>
         <origin rpy="${PI/2} 0 0" xyz="0 0 0" />
         <material name="${color}"/>
      </visual>
      <collision name="${name}_joint_c">
         <geometry>
            <cylinder length="${2*r0}" radius="${jr}" />
         </geometry>
         <origin rpy="${PI/2} 0 0" xyz="0 0 0" />
      </collision>
      <!-- Visual for main segment -->
      <visual name="${name}_segmentS_v">
         <geometry>
            <cylinder length="${l2}" radius="${r0}" />
         </geometry>
         <origin rpy="0 0 0" xyz="0 0 ${l2/2}" />
         <material name="${color}"/>
      </visual>
      <collision name="${name}_segmentS_c">
         <geometry>
            <cylinder length="${l2}" radius="${r0}" />
         </geometry>
         <origin rpy="0 0 0" xyz="0 0 ${l2/2}" />
      </collision>
    </link>
  </xacro:macro>

  <!-- macro for continuous segment -->
  <xacro:macro name="cSeg" params="parent name color">
    <joint name="${name}_joint" type="continuous">
      <axis xyz="0 0 1" />
      <parent link="${parent}"/>
      <child link="${name}_link" />
      <origin rpy="0 0 0" xyz="0.0 0.0 ${l2+jr/2}" />
    </joint>

    <link name="${name}_link">
      <inertial>
        <mass value="${mass}" />
        <origin rpy="0 0 0" xyz="0 0 0" />
        <inertia ixx="1.0" ixy="0.0" ixz="0.0"
          iyy="1.0" iyz="0.0"
          izz="1.0" />
      </inertial>
      <!-- Visual for segment -->
      <visual name="${name}_cSeg_v">
         <geometry>
         <box size="${jr} ${jr} ${jr}" />
         </geometry>
         <material name="${color}"/>
         <origin rpy="0 0 0" xyz="0 0 0" />
      </visual>
      <collision name="${name}_cSeg_c">
         <geometry>
         <box size="${jr} ${jr} ${jr}" />
         </geometry>
         <origin rpy="0 0 0" xyz="0 0 0" />
      </collision>
    </link>
  </xacro:macro>

  <!-- Macro for motor transmission -->
  <xacro:macro name="mtrT" params="jointName">
   <transmission name="${jointName}_tran">
     <type>transmission_interface/SimpleTransmission</type>
     <joint name="${jointName}">
        <hardwareInterface>PositionJointInterface</hardwareInterface>
     </joint>
     <actuator name="${jointName}_motor">
        <hardwareInterface>PositionJointInterface</hardwareInterface>
        <mechanicalReduction>1</mechanicalReduction>
     </actuator>
   </transmission>
  </xacro:macro>
  </robot>
